[ 2023-04-23 16:17:30,867 ] root - INFO - Entered the start_data_ingestion method of TrainPipeline class
[ 2023-04-23 16:17:30,867 ] root - INFO - Starting data ingestion
[ 2023-04-23 16:17:30,892 ] root - INFO - Consider Local csv file
[ 2023-04-23 16:17:32,280 ] root - INFO - Shape of dataframe: (36188, 171)
[ 2023-04-23 16:17:32,369 ] root - INFO - Shape of dataframe: (36188, 164)
[ 2023-04-23 16:17:32,369 ] root - INFO - Saving exported data into feature store file path: artifact/04_23_2023_16_17_30/data_ingestion/feature_store/sensor.csv
[ 2023-04-23 16:17:33,553 ] root - INFO - Shape of dataframe: (36188, 164)
[ 2023-04-23 16:17:33,553 ] root - INFO - Starting the train and test splittings
[ 2023-04-23 16:17:35,768 ] root - INFO - Data ingestion completed and artifact: DataIngestionArtifact(trained_file_path='artifact/04_23_2023_16_17_30/data_ingestion/ingested/train.csv', test_file_path='artifact/04_23_2023_16_17_30/data_ingestion/ingested/test.csv')
[ 2023-04-23 16:17:37,022 ] root - INFO - Missing numerical column: []
[ 2023-04-23 16:17:37,022 ] root - INFO - Valid Numerical Column : True
[ 2023-04-23 16:17:37,022 ] root - INFO - Missing numerical column: []
[ 2023-04-23 16:17:37,022 ] root - INFO - Required number of columns: 164
[ 2023-04-23 16:17:37,022 ] root - INFO - Data frame has columns: 164
[ 2023-04-23 16:17:37,022 ] root - INFO - Required number of columns: 164
[ 2023-04-23 16:17:37,022 ] root - INFO - Data frame has columns: 164
[ 2023-04-23 16:17:42,018 ] root - INFO - Data validation artifact: DataValidationArtifact(validation_status=False, valid_train_file_path='artifact/04_23_2023_16_17_30/data_ingestion/ingested/train.csv', valid_test_file_path='artifact/04_23_2023_16_17_30/data_ingestion/ingested/test.csv', invalid_train_file_path=None, invalid_test_file_path=None, drift_report_file_path='artifact/04_23_2023_16_17_30/data_validation/drift_report/report.yaml')
[ 2023-04-23 16:17:42,056 ] root - INFO - Error occurred python script name [main.py] line number [8] error message [Error occurred python script name [/home/suyodhan/Documents/Data Science Project/current_project/Heyyyyyy/sensor/pipeline/training_pipeline.py] line number [82] error message [Error occurred python script name [/home/suyodhan/Documents/Data Science Project/current_project/Heyyyyyy/sensor/pipeline/training_pipeline.py] line number [58] error message [__init__() got an unexpected keyword argument 'data_valiation_artifact']]]
